 <robot name="barrett_hand">
 <link name="world">
      <inertial>
      <origin rpy="0 0 0" xyz="0 0 0"/>
      <mass value="0"/>
      <inertia ixx="0" ixy="0" ixz="0" iyy="0" iyz="0" izz="0"/>
    </inertial>
   </link>
     <link name="forward_link">
      <inertial>
      <origin rpy="0 0 0" xyz="0 0 0"/>
      <mass value="0"/>
      <inertia ixx="0" ixy="0" ixz="0" iyy="0" iyz="0" izz="0"/>
    </inertial>
   </link>
 <link name="bh_base_link">
    <inertial>
      <mass value="0.9"/>
      <origin xyz="0 0 0"/>
      <inertia ixx="1.0" ixy="0.0" ixz="0.0" iyy="1.0" iyz="0.0" izz="1.0"/>
    </inertial>
    <visual>
      <origin rpy="0 0 0" xyz="0 0 0"/>
      <geometry>
        <mesh filename="visual/palm_280.obj"/>
      </geometry>
      <material name="Grey">
        <color rgba="0.75 0.75 0.75 1.0"/>
      </material>
    </visual>
    <collision>
      <origin rpy="0 0 0 " xyz="0 0 0"/>
      <geometry>
        <mesh filename="collision/palm_280_vhacd.obj"/>
      </geometry>
      <contact_coefficients kd="1.0" kp="1000.0" mu="0"/>
    </collision>
  </link>
  <!-- finger 3 -->
  <!-- finger 32 link -->
  <link name="bh_finger_32_link">
    <inertial>
      <mass value="0.01"/>
      <origin rpy="0 0 0" xyz="0 0 0"/>
      <inertia ixx="0.01" ixy="0" ixz="0" iyy="0.01" iyz="0" izz="0.01"/>
    </inertial>
    <visual>
      <origin rpy="0 0 0" xyz="0 0 0"/>
      <geometry>
        <mesh filename="visual/finger_32.obj"/>
      </geometry>
      <material name="Blue"/>
    </visual>
    <collision>
      <origin rpy="0 0 0" xyz="0 0 0"/>
      <geometry>
        <mesh filename="collision/finger_32_vhacd.obj"/>
      </geometry>
      <contact_coefficients kd="1.0" kp="1000.0" mu="0"/>
    </collision>
  </link>
  <!-- joint between BH_finger_31_link and BH_finger_32_link -->
  <joint name="bh_j32_joint" type="revolute">
    <parent link="bh_base_link"/>
    <child link="bh_finger_32_link"/>
    <origin rpy="1.5708 0 1.5708" xyz="0 -0.05 0.0754"/>
    <axis xyz="0 0 -1"/>
    <limit effort="30.0" lower="0.0" upper="2.44" velocity="2.0"/>
  </joint>
  <!-- finger 33 link -->
  <link name="bh_finger_33_link">
    <inertial>
      <mass value="0.01"/>
      <origin rpy="0 0 0" xyz="0 0 0"/>
      <inertia ixx="0.01" ixy="0" ixz="0" iyy="0.01" iyz="0" izz="0.01"/>
    </inertial>
    <visual>
      <origin rpy="0 0 0" xyz="0 0 0"/>
      <geometry>
        <mesh filename="visual/finger_tip_33.obj"/>
      </geometry>
      <material name="Blue"/>
    </visual>
    <collision>
      <origin rpy="0 0 0" xyz="0 0 0"/>
      <geometry>
        <mesh filename="collision/finger_tip_33_vhacd.obj"/>
      </geometry>
      <contact_coefficients kd="1.0" kp="1000.0" mu="0"/>
    </collision>
  </link>
  <!-- joint between BH_finger_32_link and BH_finger_33_link -->
  <joint name="bh_j33_joint" type="revolute">
    <parent link="bh_finger_32_link"/>
    <child link="bh_finger_33_link"/>
    <origin rpy="0 0 0" xyz="-0.069936 0.003 0"/>
    <axis xyz="0 0 -1"/>
    <mimic joint="bh_j32_joint" multiplier="0.3442622950819672"/>
    <limit effort="30.0" lower="0.0" upper="0.84" velocity="2.0"/>
  </joint>
  <!-- finger 1 -->
  <!-- finger 11 link -->
  <link name="bh_finger_11_link">
    <inertial>
      <mass value="0.01"/>
      <origin rpy="0 0 0" xyz="-0.046 0 0"/>
      <inertia ixx="0.01" ixy="0" ixz="0" iyy="0.01" iyz="0" izz="0.01"/>
    </inertial>
    <visual>
      <origin rpy="0 0 0" xyz="0 0 0"/>
      <geometry>
        <mesh filename="visual/knuckle.obj"/>
      </geometry>
      <material name="Green"/>
    </visual>
    <collision>
      <origin rpy="0 0 0" xyz="0 0 0"/>
      <geometry>
        <mesh filename="collision/knuckle_vhacd.obj"/>
      </geometry>
    </collision>
  </link>
  <!-- joint between BH_palm_link and BH_finger_11_link -->
  <joint name="bh_j11_joint" type="revolute">
    <parent link="bh_base_link"/>
    <child link="bh_finger_11_link"/>
    <origin rpy="0 0 -1.5708" xyz="0.025 0 0.0415"/>
    <axis xyz="0 0 -1"/>
    <limit effort="30.0" lower="0" upper="3.1416" velocity="2.0"/>
  </joint>
  <!-- finger 12 link -->
  <link name="bh_finger_12_link">
    <inertial>
      <mass value="0.01"/>
      <origin rpy="0 0 0" xyz="0 0 0"/>
      <inertia ixx="0.01" ixy="0" ixz="0" iyy="0.01" iyz="0" izz="0.01"/>
    </inertial>
    <visual>
      <origin rpy="0 0 0" xyz="0 0 0"/>
      <geometry>
        <mesh filename="visual/finger_12.obj"/>
      </geometry>
      <material name="Blue"/>
    </visual>
    <collision>
      <origin rpy="0 0 0" xyz="0 0 0"/>
      <geometry>
        <mesh filename="collision/finger_12_vhacd.obj"/>
      </geometry>
      <contact_coefficients kd="1.0" kp="1000.0" mu="0"/>
    </collision>
  </link>
  <!-- joint between BH_finger_11_link and BH_finger_12_link -->
  <joint name="bh_j12_joint" type="revolute">
    <parent link="bh_finger_11_link"/>
    <child link="bh_finger_12_link"/>
    <origin rpy="1.5708 0 0" xyz="-0.05 0 0.0339"/>
    <axis xyz="0 0 -1"/>
    <limit effort="30.0" lower="0.0" upper="2.44" velocity="2.0"/>
  </joint>
  <!-- finger 13 link -->
  <link name="bh_finger_13_link">
    <inertial>
      <mass value="0.01"/>
      <origin rpy="0 0 0" xyz="0 0 0"/>
      <inertia ixx="0.01" ixy="0" ixz="0" iyy="0.01" iyz="0" izz="0.01"/>
    </inertial>
    <visual>
      <origin rpy="0 0 0" xyz="0 0 0"/>
      <geometry>
        <mesh filename="visual/finger_tip_13.obj"/>
      </geometry>
      <material name="Blue"/>
    </visual>
    <collision>
      <origin rpy="0 0 0" xyz="0 0 0"/>
      <geometry>
        <mesh filename="collision/finger_tip_13_vhacd.obj"/>
      </geometry>
      <contact_coefficients kd="1.0" kp="1000.0" mu="0"/>
    </collision>
  </link>
  <!-- joint between BH_finger_12_link and BH_finger_13_link -->
  <joint name="bh_j13_joint" type="revolute">
    <parent link="bh_finger_12_link"/>
    <child link="bh_finger_13_link"/>
    <origin rpy="0 0 0" xyz="-0.069936 0.003 0"/>
    <axis xyz="0 0 -1"/>
    <mimic joint="bh_j12_joint" multiplier="0.3442622950819672"/>
    <limit effort="30.0" lower="0.0" upper="0.84" velocity="2.0"/>
  </joint>
  <!-- finger 2 -->
  <!-- finger 21 link -->
  <link name="bh_finger_21_link">
    <inertial>
      <mass value="0.01"/>
      <origin rpy="0 0 0" xyz="-0.046 0 0"/>
      <inertia ixx="0.01" ixy="0" ixz="0" iyy="0.01" iyz="0" izz="0.01"/>
    </inertial>
    <visual>
      <origin rpy="0 0 0" xyz="0 0 0"/>
      <geometry>
        <mesh filename="visual/knuckle_2.obj"/>
      </geometry>
      <material name="Green"/>
    </visual>
    <collision>
      <origin rpy="0 0 0" xyz="0 0 0"/>
      <geometry>
        <mesh filename="collision/knuckle_2_vhacd.obj"/>
      </geometry>
    </collision>
  </link>
  <!-- joint between BH_palm_link and BH_finger_21_link -->
  <joint name="bh_j21_joint" type="revolute">
    <parent link="bh_base_link"/>
    <child link="bh_finger_21_link"/>
    <origin rpy="0 0 -1.5708" xyz="-0.025 0 0.0415"/>
    <axis xyz="0 0 1"/>
    <mimic joint="bh_j11_joint" multiplier="1"/>
    <limit effort="30.0" lower="0" upper="3.1416" velocity="2.0"/>
  </joint>
  <!-- finger 12 link -->
  <link name="bh_finger_22_link">
    <inertial>
      <mass value="0.01"/>
      <origin rpy="0 0 0" xyz="0 0 0"/>
      <inertia ixx="0.01" ixy="0" ixz="0" iyy="0.01" iyz="0" izz="0.01"/>
    </inertial>
    <visual>
      <origin rpy="0 0 0" xyz="0 0 0"/>
      <geometry>
        <mesh filename="visual/finger_22.obj"/>
      </geometry>
      <material name="Blue"/>
    </visual>
    <collision>
      <origin rpy="0 0 0" xyz="0 0 0"/>
      <geometry>
        <mesh filename="collision/finger_22_vhacd.obj"/>
      </geometry>
      <contact_coefficients kd="1.0" kp="1000.0" mu="0"/>
    </collision>
  </link>
  <!-- joint between BH_finger_21_link and BH_finger_22_link -->
  <joint name="bh_j22_joint" type="revolute">
    <parent link="bh_finger_21_link"/>
    <child link="bh_finger_22_link"/>
    <origin rpy="1.5708 -8.8281E-17 0" xyz="-0.05 0 0.0339"/>
    <axis xyz="0 0 -1"/>
    <limit effort="30.0" lower="0.0" upper="2.44" velocity="2.0"/>
  </joint>
  <!-- finger 23 link -->
  <link name="bh_finger_23_link">
    <inertial>
      <mass value="0.01"/>
      <origin rpy="0 0 0" xyz="0 0 0"/>
      <inertia ixx="0.01" ixy="0" ixz="0" iyy="0.01" iyz="0" izz="0.01"/>
    </inertial>
    <visual>
      <origin rpy="0 0 0" xyz="0 0 0"/>
      <geometry>
        <mesh filename="visual/finger_tip_23.obj"/>
      </geometry>
      <material name="Blue"/>
    </visual>
    <collision>
      <origin rpy="0 0 0" xyz="0 0 0"/>
      <geometry>
        <mesh filename="collision/finger_tip_23_vhacd.obj"/>
      </geometry>
      <contact_coefficients kd="1.0" kp="1000.0" mu="0"/>
    </collision>
  </link>
  <!-- joint between BH_finger_22_link and BH_finger_23_link -->
  <joint name="bh_j23_joint" type="revolute">
    <parent link="bh_finger_22_link"/>
    <child link="bh_finger_23_link"/>
    <origin rpy="0 0 0" xyz="-0.069936 0.003 0"/>
    <axis xyz="0 0 -1"/>
    <mimic joint="bh_j22_joint" multiplier="0.3442622950819672"/>
    <limit effort="30.0" lower="0.0" upper="0.84" velocity="2.0"/>
  </joint>
    <joint name="rotation_joint" type="revolute">
    <origin rpy="0 0 0" xyz="0 0 0"/>
    <parent link="world"/>
    <child link="forward_link"/>
    <axis xyz="0 0 1"/>
    <limit effort="1000" lower="-3.14" upper="3.14"/>
  </joint>
  <joint name="forward_joint" type="prismatic">
    <origin rpy="0 0 0" xyz="0 0 0"/>
    <parent link="forward_link"/>
    <child link="bh_base_link"/>
    <axis xyz="0 0 1"/>
    <limit effort="1000" lower="-10" upper="10"/>
  </joint>
  </robot>